---
# 这是文章的标题
title: 第四章-异常与错误
# 这是页面的图标
icon: pepper-hot
# 这是侧边栏的顺序
order: 4
# 设置作者
author: god23bin
# 设置写作时间
date: 2024-01-18 13:14:13
# 一个页面可以有多个分类
category:
  - Java基础
# 一个页面可以有多个标签
tag:
  - Java
---

## 第四章-异常与错误

**异常（Exception）**是程序执行过程中出现的问题。当**异常**发生时，程序的正常流程会被打乱，程序还会终止运行，这种情况是我们不想看到的，所以，需要对这些异常进行处理，防止程序停止运行。

### 一、异常分类

**受检查异常（Checked exceptions）**：指编译器在编译时会检查的异常，也称为编译时异常。这些异常不能简单地被忽略，我们作为开发者，应该处理这些异常。

举个例子，你想要读取某个文件，但是这个文件并不存在，那么程序就会发生一个异常（*FileNotFoundException*），编译器就会提醒开发者去处理这个异常。

**不受检查的异常（Unchecked exceptions）**：这种不受检查的异常是在程序运行时会发生的，所以也称为运行时异常。这种就包含了 Bug，比如出现逻辑错误或者不合适的 API 调用，运行时异常在编译的时候是发现不了的。常见的比如有数组越界异常。

**错误（Error）**：这种问题就不是程序本身的问题，而是虚拟机的问题，比如堆栈溢出，OOM 等等。

### 二、异常层次结构

![异常层次结构](https://www.tutorialspoint.com/java/images/exceptions1.jpg)

所有异常类都是 java.lang.Exception 的子类，错误则对应的 Error 类

### 三、捕获异常

对于可能发生异常的地方，我们可以对其进行尝试捕获异常，进而处理异常，防止程序发生异常时停止运行。

我们可以使用 try 和 catch 关键字组合来捕获异常，这个组合放在可能发生异常的代码周围。

语法如下：

```java
try {
   // 受保护的代码（可能发生异常的代码）
} catch (ExceptionName e1) {
   // Catch 块，处理异常，比如打印是什么异常
}
```

当异常发生时，发生的异常由与其关联的 catch 块处理。每个 try 块后面都应该紧跟着一个 catch 块或 finally 块。

catch 语句中声明我们尝试捕获的异常类型。如果发生的异常类型在 catch 块中包含了，则异常将传递到 catch 块，就像将参数传递到方法中一样。

示例：

```java
public class ExcepTest {
   public static void main(String args[]) {
      try {
         int a[] = new int[2];
         System.out.println("访问数组元素 a[3]:" + a[3]);
      } catch (ArrayIndexOutOfBoundsException e) {
         System.out.println("异常抛出:" + e);
      }
      System.out.println("这里处于 try catch 块之外");
   }
}
```

输出：

```console
异常抛出:java.lang.ArrayIndexOutOfBoundsException: 3
这里处于 try catch 块之外
```

#### 多个 catch 块

一个 try 块后面可以跟多个 catch 块，语法如下：

```java
try {
   // 受保护的代码（可能发生异常的代码）
} catch (ExceptionType1 e1) {
   // Catch 块
} catch (ExceptionType2 e2) {
   // Catch 块
} catch (ExceptionType3 e3) {
   // Catch 块
}
```

如果受保护的代码中发生异常，则该异常将被抛出到列表中的第一个 catch 块。如果抛出的异常的数据类型与 ExceptionType1 匹配，则会在那里捕获该异常。如果不是，则异常将传递到第二个 catch 语句。以此类推，直到异常被捕获或通过所有 catch，在这种情况下，当前方法停止执行，并将异常抛出到调用堆栈上的前一个方法。

示例：

```java
try {
   file = new FileInputStream(fileName);
   x = (byte) file.read();
} catch (IOException i) {
   i.printStackTrace();
   return -1;
} catch (FileNotFoundException f) {
   f.printStackTrace();
   return -1;
}
```

#### 单个 catch 捕获多个异常

语法如下：

```java
catch (IOException | FileNotFoundException ex) {
   logger.log(ex);
   throw ex;
}
```

### 四、throws 和 throw 关键字

如果一个方法不处理受检查的异常，那么就需要向调用方抛出这个异常，告知调用方该方法没有处理异常，异常交给调用方处理，这时就需要使用 throws 关键字，throws 关键字跟在方法签名后面。

如果我们自己抛出一个异常，或者一个新的异常实例，我们就需要使用 throw 关键字。

注意理解 throws 和 throw 关键字之间的区别：throws 用于推迟处理受检查的异常，而 throw 用于显式调用异常。

示例：

```java
public class className {

   public void deposit(double amount) throws RemoteException {
      // 手动抛出一个新的异常实例，但是我们没有捕获，所以需要在方法签名后面进行声明，告知调用方这里没有处理异常
      throw new RemoteException();
   }
   
}
```

### 五、finally 块

finally 块位于 try 块或 catch 块之后。无论是否发生异常，finally 代码块始终都会执行。

语法如下：

```java
try {
   // 受保护的代码（可能发生异常的代码）
} catch (ExceptionType1 e1) {
   // Catch 块
} catch (ExceptionType2 e2) {
   // Catch 块
} catch (ExceptionType3 e3) {
   // Catch 块
} finally {
   // 永远都会执行的 finally 块
}
```

- 没有 try，那么就没有 catch，它们总是成对出现。而 finally 则是非必要的。
- try、catch、finally 块之间不能出现任何代码。

### 六、try-with-resources

一般来说，当我们使用流、连接等任何资源时，我们必须使用finally块显式关闭它们。

示例：

```java
public class ReadData_Demo {

   public static void main(String args[]) {
      FileReader fr = null;		
      try {
         File file = new File("file.txt");
         fr = new FileReader(file);
         char [] a = new char[50];
         fr.read(a); // 读取文件内容到 a 数组中
         for(char c : a)
         System.out.print(c); // 遍历数组打印字符
      } catch (IOException e) {
         e.printStackTrace();
      }finally {
         try {
            fr.close(); // 关闭资源
         } catch (IOException ex) {		
            ex.printStackTrace();
         }
      }
   }
}
```

Java 7 中引入的一种新的异常处理机制，**try-with-resources** 也称为**自动资源管理**，它会自动关闭 try catch 块内使用的资源。要使用此语句，我们只需在括号内声明所需的资源，那么创建的资源将在块末尾自动关闭。

以下是 try-with-resources 语句的语法：

```java
try (FileReader fr = new FileReader("file path")) {
   // 使用资源
} catch () {
   // 捕获异常
}
```

示例：

```java
public class Try_withDemo {

   public static void main(String args[]) {
      try (FileReader fr = new FileReader("E://file.txt")) {
         char [] a = new char[50];
         fr.read(a);   // 读取文件内容到 a 数组中
         for(char c : a)
         System.out.print(c);   // 遍历数组打印字符
      } catch (IOException e) {
         e.printStackTrace();
      }
   }
}
```

- 要使用带有 try-with-resources 语句的类，它应该实现 **AutoCloseable** 接口，并且它的 **close()** 方法在运行时自动调用。
- 我们可以在 try-with-resources 语句中声明多个类。
- 当我们在 try-with-resources 语句的 try 块中声明多个类时，这些类将以相反的顺序关闭。
- 除了括号内的资源声明之外，所有内容都与 try 块的正常 try/catch 块相同。
- try 中声明的资源在 try 块开始之前被实例化。
- 在 try 块中声明的资源被隐式声明为 final。

### 七、自定义异常

- 所有异常都必须是 Throwable 的子类。
- 如果要编写由 Handle 或 Declare Rule 自动强制执行的已检查异常，则需要继承 Exception 类。
- 如果要编写运行时异常，则需要继承 RuntimeException 类。
- 异常类与其他类一样，也包含有用的字段和方法。

示例：自定义一个资金不足异常 InsufficientFundsException，这是一个受检查异常，因为继承了 Exception 类。

```java
public class InsufficientFundsException extends Exception {
   private double amount;
   
   public InsufficientFundsException(double amount) {
      this.amount = amount;
   }
   
   public double getAmount() {
      return amount;
   }
}
```

演示如何使用自定义的异常：

```java
public class CheckingAccount {
   // 余额
   private double balance;
   private int number;
   
   public CheckingAccount(int number) {
      this.number = number;
   }
   
   // 存钱
   public void deposit(double amount) {
      balance += amount;
   }
   
   // 抛出自定义的异常
   // 取钱
   public void withdraw(double amount) throws InsufficientFundsException {
      // 要取的钱比余额小，那么可以取出
      if (amount <= balance) {
         balance -= amount;
      } else {
         // 取的钱大于余额，不够取，资金不足
         double needs = amount - balance;
         throw new InsufficientFundsException(needs);
      }
   }
   
   public double getBalance() {
      return balance;
   }
   
   public int getNumber() {
      return number;
   }
}
```

```java
public class BankDemo {

   public static void main(String [] args) {
      CheckingAccount c = new CheckingAccount(101);
      System.out.println("存入 500 元...");
      c.deposit(500.00);
      
      try {
         // 取钱方法是有向调用者抛出异常的，所以这里调用时需要使用 try catch 捕获异常
         System.out.println("\n取出 100 元...");
         c.withdraw(100.00);
         System.out.println("\n取出 600 元...");
         c.withdraw(600.00);
      } catch (InsufficientFundsException e) {
         System.out.println("抱歉，你缺钱: " + e.getAmount());
         e.printStackTrace();
      }
   }
}
```

输出：

```console
存入 500 元...

取出 100 元...

取出 600 元...
抱歉，你缺钱: $200.0
InsufficientFundsException
         at CheckingAccount.withdraw(CheckingAccount.java:25)
         at BankDemo.main(BankDemo.java:13)
```

